<?xml version="1.0" encoding="utf-8"?>

<!--
robotiq-3f-gripper_articulated_macro(prefix)

Creates an articulated robotiq-3f-gripper hand with the passed in prefix.  If there
is only one hand in the urdf then an empty prefix can be used "".  If
there are multiple hands then a prefix followed by an "_" is needed.

-->
<robot xmlns:xacro="http://ros.org/wiki/xacro">

    <xacro:include filename="$(find robotiq_3f_gripper_visualization)/urdf/robotiq-hand.xacro" />

    <xacro:macro name="robotiq_articulated_macro" params="prefix connected_to:='' rpy:='0 0 0' xyz:='0 0 0'">
    <xacro:robotiq_hand prefix="${prefix}finger_1_"/>
    <xacro:robotiq_hand prefix="${prefix}finger_2_"/>
    <xacro:robotiq_hand prefix="${prefix}finger_middle_"/>

    <xacro:unless value="${connected_to == ''}">
      <joint name="${prefix}ur5_robotiq_joint" type="fixed">
        <parent link="${connected_to}"/>
        <child link="${prefix}palm"/>
        <origin xyz="${xyz}" rpy="${rpy}"/>
      </joint>
    </xacro:unless>

		<!-- link list -->
		<link name="${prefix}palm">
			<visual>
				<geometry>
                	<mesh filename="package://robotiq_3f_gripper_visualization/meshes/robotiq-3f-gripper_articulated/visual/palm.STL" />
				</geometry>
				<material name="gray">
					<color rgba="0.2 0.2 0.2 1"/>
				</material>
			</visual>
			<collision>
				<geometry>
                    <mesh filename="package://robotiq_3f_gripper_visualization/meshes/robotiq-3f-gripper_articulated/collision/palm.STL" />
				</geometry>
				<material name="yellow">
					<color rgba="0 1 1 1"/>
				</material>
			</collision>
		</link>


		<gazebo reference="${prefix}palm">
            <material>Gazebo/Black</material>
       	</gazebo>


		<link name="${prefix}tool0"/>

        <gazebo reference="${prefix}tool0">
            <material>Gazebo/Blue</material>
        </gazebo>


        <inertial>
            <origin xyz="0 0 0" rpy="0 0 0"/>
            <mass value="0.5"/>
            <inertia ixx="0.006012" ixy="0.000079" ixz="-0.00024" iyy="0.012892" iyz="0" izz="0.002435" />
        </inertial>
		<!-- end of link list -->
		<!-- joint list -->

		<joint name="${prefix}palm_finger_1_joint" type="revolute">
			<parent link="${prefix}palm"/>
			<child link="${prefix}finger_1_link_0"/>
			<axis xyz="0 1 0"/>
			<origin xyz="-0.0455 0.0214 0.036" rpy="0 3.1416 -1.57"/>
			<limit lower="-0.1784" upper="0.192" effort="100" velocity="100"/>
		</joint>

        <transmission name="${prefix}palm_finger_1_joint_trans">
            <type>transmission_interface/SimpleTransmission</type>
            <joint name="${prefix}palm_finger_1_joint" >
                <hardwareInterface>hardware_interface/VelocityJointInterface</hardwareInterface>
            </joint>
            <actuator name="${prefix}palm_finger_1_joint_motor">
                <hardwareInterface>hardware_interface/VelocityJointInterface</hardwareInterface>
                <mechanicalReduction>1</mechanicalReduction>
            </actuator>
        </transmission>


		<joint name="${prefix}palm_finger_2_joint" type="revolute">
			<parent link="${prefix}palm"/>
			<child link="${prefix}finger_2_link_0"/>
			<axis xyz="0 1 0"/>
			<origin xyz="-0.0455 0.0214 -0.036" rpy="0 3.1416 -1.57"/>
			<limit lower="-0.192" upper="0.1784" effort="100" velocity="100"/>
		</joint>

        <transmission name="${prefix}palm_finger_2_joint_trans">
            <type>transmission_interface/SimpleTransmission</type>
            <joint name="${prefix}palm_finger_2_joint" >
                <hardwareInterface>hardware_interface/VelocityJointInterface</hardwareInterface>
            </joint>
            <actuator name="${prefix}palm_finger_2_joint_motor">
                <hardwareInterface>hardware_interface/VelocityJointInterface</hardwareInterface>
                <mechanicalReduction>1</mechanicalReduction>
            </actuator>
        </transmission>


		<joint name="${prefix}palm_finger_middle_joint" type="fixed">
			<parent link="${prefix}palm"/>
			<child link="${prefix}finger_middle_link_0"/>
			<axis xyz="0 0 1"/>
			<origin xyz="0.0455 0.0214 0" rpy="0 0 1.57"/>
		</joint>


        <!--transmission name="${prefix}palm_finger_middle_joint_trans">
            <type>transmission_interface/SimpleTransmission</type>
            <joint name="${prefix}palm_finger_middle_joint" >
                <hardwareInterface>hardware_interface/VelocityJointInterface</hardwareInterface>
            </joint>
            <actuator name="${prefix}palm_finger_middle_joint_motor">
                <hardwareInterface>hardware_interface/VelocityJointInterface</hardwareInterface>
                <mechanicalReduction>1</mechanicalReduction>
            </actuator>
        </transmission-->


		<joint name="${prefix}palm_tool0" type="fixed">
			<parent link="${prefix}palm"/>
			<child link="${prefix}tool0"/>
			<origin xyz="0.0 0.0875 0.0" rpy="0 0 1.5707"/>
		</joint>
		<!-- end of joint list -->
	</xacro:macro>


	
</robot>
